{
  "id": "19ce3c03-1bb4-4649-9ae5-fbd3a1e95927",
  "title": "Effective Exception Handling in Kotlin Coroutines : Android",
  "link": "https://proandroiddev.com/effective-exception-handling-in-kotlin-coroutines-android-6925d0d95c21?source=rss----c72404660798---4",
  "description": "",
  "author": "Shahinoor Shahin",
  "published": "Tue, 24 Dec 2024 16:52:51 GMT",
  "source": "https://proandroiddev.com/feed",
  "categories": [
    "coroutines-in-kotlin",
    "android",
    "android-app-development",
    "androiddev",
    "kotlin"
  ],
  "byline": "Shahinoor Shahin",
  "length": 12866,
  "excerpt": "Error handling is a fundamental aspect of any robust application. Kotlin, being a modern programming language, offers several mechanisms to handle errors effectively and gracefully. Kotlin uses…",
  "siteName": "ProAndroidDev",
  "favicon": "https://miro.medium.com/v2/resize:fill:256:256/1*A8VytPZQhvUf_MG6hm_Dlw.png",
  "text": "Error handling is a fundamental aspect of any robust application. Kotlin, being a modern programming language, offers several mechanisms to handle errors effectively and gracefully.Photo by Tormius on Unsplash1. Exception Handling: Try-Catch BlocksKotlin uses try-catch blocks for handling exceptions, similar to Java. This mechanism is straightforward and familiar to developers coming from Java or similar languages.fun divide(a: Int, b: Int): Int { return try { a / b } catch (e: ArithmeticException) { println(\"Error: ${e.message}\") 0 // Return a default value }}fun main() { val result = divide(10, 0) println(\"Result: $result\")}In this example, if a division by zero occurs, the catch block handles the ArithmeticException and provides a default value.Explanation:The try block contains the code that might throw an exception.The catch block handles specific exceptions, like ArithmeticException in this case.This approach ensures that the program doesn’t crash and instead recovers gracefully.“Why did the developer bring a ladder to the code review? To handle high-level exceptions!”2. Checked vs. Unchecked ExceptionsUnlike Java, Kotlin doesn’t differentiate between checked and unchecked exceptions. All exceptions are unchecked, meaning that the compiler doesn’t force you to handle them. This design simplifies code and avoids boilerplate.Explanation:Checked exceptions require explicit handling, often leading to verbose code.Kotlin’s approach aligns with modern development practices, emphasizing developer responsibility over compiler enforcement.3. Custom ExceptionsKotlin allows developers to define custom exceptions for more granular error handling.class InvalidInputException(message: String) : Exception(message)fun validateInput(input: Int) { if (input \u003c 0) { throw InvalidInputException(\"Input must be non-negative\") }}fun main() { try { validateInput(-5) } catch (e: InvalidInputException) { println(\"Caught Exception: ${e.message}\") }}Explanation:Custom exceptions provide clarity by allowing you to communicate domain-specific issues.This makes debugging easier as the exception conveys exactly what went wrong.Throwing custom exceptions is like saying, “This is my circus, and these are my monkeys.”Custom exceptions help in creating domain-specific error-handling mechanisms.4. Null Safety and the Elvis OperatorKotlin’s null safety features significantly reduce the chances of NullPointerException. The Elvis operator (?:) provides a concise way to handle nullable types.fun getLength(str: String?): Int { return str?.length ?: 0}fun main() { println(getLength(null)) // Outputs: 0}Explanation:The ?. operator safely accesses properties of nullable types.The Elvis operator (?:) provides a default value if the expression to its left evaluates to null.Null safety: Because Kotlin knows that “To null is human, but to not null is divine.”Here, the Elvis operator ensures that a default value is returned if str is null.5. Double Bang OperatorThe double bang operator (!!) is used to explicitly assert that an expression is non-null. When you use !!, you tell the compiler: \"I know this value is not null, so proceed as if it's non-null.\"If the value is null, it throws a NullPointerException (NPE) at runtime. This operator is risky and should be used sparingly because it bypasses Kotlin's built-in null safety.Syntax of the Double Bang Operatorval nonNullableValue = nullableValue!!If nullableValue is non-null, the program continues normally.If nullableValue is null, the program crashes with a NullPointerException.Example 1 : Basic Exception Handling with !!To handle exceptions caused by the double bang operator, you can wrap it in a try-catch block.fun main() { val name: String? = null try { val length = name!!.length // Forces an exception if `name` is null println(\"Length of the name: $length\") } catch (e: NullPointerException) { println(\"Caught a NullPointerException: ${e.message}\") }}Output:Caught a NullPointerException: nullHere, the NullPointerException is caught, and the program doesn't crash.When to Use !!You should avoid !! whenever possible. Use it only when:You are 100% certain that a value is non-null at runtime.You want the program to explicitly throw an exception when a null value is unexpected.Example 2: Legitimate Use Case for !!fun getNameLength(name: String?): Int { return name!!.length // You are certain `name` is not null here}fun main() { val name: String? = \"Kotlin\" println(\"Length of the name: ${getNameLength(name)}\") // Works as expected}Here, !! is used when you are certain that name will not be null.The double bang operator is a powerful but dangerous tool. It’s better to rely on Kotlin’s null safety features (?., ?:, let, if, etc.) to handle nulls gracefully. Reserve !! for situations where you need strict null-safety enforcement and are willing to risk throwing an exception.6. Result TypeKotlin’s Result type is a functional approach to handle success and failure cases without exceptions.fun safeDivide(a: Int, b: Int): Result\u003cInt\u003e { return if (b != 0) { Result.success(a / b) } else { Result.failure(ArithmeticException(\"Division by zero\")) }}fun main() { val result = safeDivide(10, 0) result.onSuccess { println(\"Result: $it\") }.onFailure { println(\"Error: ${it.message}\") }}Explanation:Result encapsulates success or failure, avoiding the need for explicit exception handling.The onSuccess and onFailure methods allow you to handle both outcomes succinctly.It’s like playing a game of chance: “Heads, you succeed. Tails, you divide by zero.”7. \"runCatching\" for Exception HandlingUsing Result provides a clear separation of successful and error outcomes, promoting functional programming practices.In Kotlin, the runCatching function is a handy utility for encapsulating the result of a block of code execution. It simplifies exception handling by wrapping the result of a code block in a Result object. If the code executes successfully, it encapsulates the result as a Success. If an exception occurs, it catches it and encapsulates it as a Failure.Here’s a breakdown of how runCatching works:Input: A lambda block of code to execute.Output: A Result object that can represent either:Success if the block executes without exceptions.Failure if any exception (of type Throwable) occurs during execution.This allows you to handle errors and process results more functionally.fun main() { val result = runCatching { // Block of code that might throw an exception val number = \"123\".toInt() // This will succeed number / 0 // This will throw an ArithmeticException } // Handling the result result.onSuccess { value -\u003e println(\"Success! The result is $value\") }.onFailure { exception -\u003e println(\"Failure! Caught exception: ${exception.message}\") }}Explanation:The block in runCatching contains code that attempts to:Parse a string to an integer (\"123\".toInt()) – successful.Divide the number by zero — throws an ArithmeticException.2. Since the second operation fails, the exception is caught, and the result is encapsulated as Failure.3. The result is then handled:onSuccess block: Will execute if the operation succeeds.onFailure block: Will execute if an exception is caught, and it provides the exception details.Practical Use Case: Reading a Filefun readFileContent(fileName: String): String { return runCatching { // Simulating reading a file if (fileName.isBlank()) throw IllegalArgumentException(\"File name cannot be blank\") \"File content of $fileName\" }.getOrElse { exception -\u003e \"Error occurred: ${exception.message}\" }}fun main() { println(readFileContent(\"document.txt\")) // Successful case println(readFileContent(\"\")) // Failure case}Output:File content of document.txtError occurred: File name cannot be blankKey Benefits of runCatching:Concise exception handling.Avoids boilerplate try-catch blocks.Functional programming style: chaining methods like onSuccess, onFailure, map, and getOrElse for clean handling of both success and failure scenarios.Error Handling in Coroutines in Kotlin: A Deep DiveKotlin coroutines provide a powerful way to write asynchronous and non-blocking code. However, handling errors effectively in coroutines requires a good understanding of coroutine-specific mechanisms and best practices. Below are key strategies for error handling in coroutines.8. Exception Handling in CoroutinesIn Kotlin, exceptions in coroutines are propagated differently based on the coroutine builder used. The most commonly used builders are launch and async.launch: Exceptions are propagated to the CoroutineExceptionHandler.async: Exceptions are deferred and must be caught when accessing the result.import kotlinx.coroutines.*fun main() = runBlocking { val job = launch { try { println(\"Throwing exception in launch\") throw IllegalArgumentException(\"Exception in launch\") } catch (e: Exception) { println(\"Caught ${e.message}\") } } job.join() val deferred = async { println(\"Throwing exception in async\") throw IllegalArgumentException(\"Exception in async\") } try { deferred.await() } catch (e: Exception) { println(\"Caught ${e.message}\") }}Explanation:launch: Automatically propagates uncaught exceptions to its parent or a CoroutineExceptionHandler.async: Requires explicit handling when the result is awaited.“Async errors: Because sometimes you just need a little delay to let the chaos unfold.”9. CoroutineExceptionHandlerThe CoroutineExceptionHandler is a dedicated mechanism for handling uncaught exceptions in coroutines launched via launch.import kotlinx.coroutines.*fun main() = runBlocking { val handler = CoroutineExceptionHandler { _, exception -\u003e println(\"Caught ${exception.message} in CoroutineExceptionHandler\") } val job = launch(handler) { throw IllegalStateException(\"Unhandled exception\") } job.join()}Explanation:Acts as a global handler for uncaught exceptions in coroutines.Can be attached to a CoroutineScope or individual coroutines.“CoroutineExceptionHandler: The guardian angel your coroutines never knew they needed.”10. SupervisionJob and SupervisorScopeWhen working with structured concurrency, SupervisorJob and supervisorScope allow child coroutines to fail independently without affecting others.import kotlinx.coroutines.*fun main() = runBlocking { supervisorScope { val child1 = launch { println(\"Child 1 is running\") throw RuntimeException(\"Child 1 failed\") } val child2 = launch { println(\"Child 2 is running\") delay(1000) println(\"Child 2 completed\") } try { child1.join() } catch (e: Exception) { println(\"Caught exception from child 1: ${e.message}\") } child2.join() }}Explanation:SupervisorJob ensures that failure in one child coroutine doesn’t cancel others.supervisorScope works similarly, providing isolation for child coroutine errors.“Supervision: Because even coroutines need a responsible adult in the room.”Why Exception Handling is Important in CoroutinesException handling in coroutines is critical due to their asynchronous and concurrent nature. Here’s why:Uncaught Exceptions Can Crash Your Application: Unhandled exceptions in coroutines launched in the GlobalScope or at the top level may lead to application crashes. This is especially risky in production environments.Complex Error Propagation: Coroutines are designed to handle concurrency. Without proper error handling, debugging and tracing the source of exceptions can become a nightmare.Structured Concurrency Needs Predictability: In structured concurrency, the parent coroutine supervises its children. Unhandled exceptions in child coroutines can affect parent coroutines, causing unintended cancellations.Graceful Recovery: Applications often need to continue functioning even after encountering an error. Handling exceptions enables recovery mechanisms, such as retries or fallback logic.ConclusionKotlin provides powerful error-handling tools, from traditional try-catch blocks to coroutine-specific mechanisms like CoroutineExceptionHandler and supervisorScope. Mastering these techniques ensures your applications are robust, maintainable, and resilient to errors.Remember, good error handling isn’t just about preventing crashes — it’s about ensuring that your application can recover gracefully and continue to provide a great user experience. And if all else fails, at least you’ll have some funny error messages to entertain your users!",
  "image": "https://miro.medium.com/v2/da:true/resize:fit:1200/0*XDQwb6RFBdrdcEoa",
  "html": "\u003cdiv id=\"readability-page-1\" class=\"page\"\u003e\u003cdiv\u003e\u003cdiv\u003e\u003cdiv aria-hidden=\"false\"\u003e\u003ca href=\"https://medium.com/@shahin.cse.sust?source=post_page---byline--6925d0d95c21--------------------------------\" rel=\"noopener follow\"\u003e\u003cdiv\u003e\u003cp\u003e\u003cimg alt=\"Shahinoor Shahin\" src=\"https://miro.medium.com/v2/resize:fill:88:88/1*TwdbePvw5iieP79PBIrCNQ.jpeg\" width=\"44\" height=\"44\" loading=\"lazy\" data-testid=\"authorPhoto\"/\u003e\u003c/p\u003e\u003c/div\u003e\u003c/a\u003e\u003c/div\u003e\u003cdiv aria-hidden=\"false\"\u003e\u003ca href=\"https://proandroiddev.com/?source=post_page---byline--6925d0d95c21--------------------------------\" rel=\"noopener  ugc nofollow\"\u003e\u003cdiv\u003e\u003cp\u003e\u003cimg alt=\"ProAndroidDev\" src=\"https://miro.medium.com/v2/resize:fill:48:48/1*XVtdl45m8YaYrPI4buJ5yQ.png\" width=\"24\" height=\"24\" loading=\"lazy\" data-testid=\"publicationPhoto\"/\u003e\u003c/p\u003e\u003c/div\u003e\u003c/a\u003e\u003c/div\u003e\u003c/div\u003e\u003cp id=\"93ee\"\u003e\u003cspan\u003eE\u003c/span\u003error handling is a fundamental aspect of any robust application. Kotlin, being a modern programming language, offers several mechanisms to handle errors effectively and gracefully.\u003c/p\u003e\u003cfigure\u003e\u003cfigcaption\u003ePhoto by \u003ca href=\"https://unsplash.com/@tormius?utm_source=medium\u0026amp;utm_medium=referral\" rel=\"noopener ugc nofollow\" target=\"_blank\"\u003eTormius\u003c/a\u003e on \u003ca href=\"https://unsplash.com/?utm_source=medium\u0026amp;utm_medium=referral\" rel=\"noopener ugc nofollow\" target=\"_blank\"\u003eUnsplash\u003c/a\u003e\u003c/figcaption\u003e\u003c/figure\u003e\u003ch2 id=\"5a98\"\u003e1. Exception Handling: Try-Catch Blocks\u003c/h2\u003e\u003cp id=\"ca57\"\u003eKotlin uses \u003ccode\u003etry-catch\u003c/code\u003e blocks for handling exceptions, similar to Java. This mechanism is straightforward and familiar to developers coming from Java or similar languages.\u003c/p\u003e\u003cpre\u003e\u003cspan id=\"b430\"\u003efun divide(a: Int, b: Int): Int {\u003cbr/\u003e    return try {\u003cbr/\u003e        a / b\u003cbr/\u003e    } catch (e: ArithmeticException) {\u003cbr/\u003e        println(\u0026#34;Error: ${e.message}\u0026#34;)\u003cbr/\u003e        0 // Return a default value\u003cbr/\u003e    }\u003cbr/\u003e}\u003cp\u003efun main() {\u003cbr/\u003e    val result = divide(10, 0)\u003cbr/\u003e    println(\u0026#34;Result: $result\u0026#34;)\u003cbr/\u003e}\u003c/p\u003e\u003c/span\u003e\u003c/pre\u003e\u003cp id=\"fde6\"\u003eIn this example, if a division by zero occurs, the \u003ccode\u003ecatch\u003c/code\u003e block handles the \u003ccode\u003eArithmeticException\u003c/code\u003e and provides a default value.\u003c/p\u003e\u003cp id=\"9e95\"\u003e\u003cstrong\u003eExplanation:\u003c/strong\u003e\u003c/p\u003e\u003cul\u003e\u003cli id=\"ac13\"\u003eThe \u003ccode\u003etry\u003c/code\u003e block contains the code that might throw an exception.\u003c/li\u003e\u003cli id=\"f5b5\"\u003eThe \u003ccode\u003ecatch\u003c/code\u003e block handles specific exceptions, like \u003ccode\u003eArithmeticException\u003c/code\u003e in this case.\u003c/li\u003e\u003cli id=\"22d3\"\u003eThis approach ensures that the program doesn’t crash and instead recovers gracefully.\u003c/li\u003e\u003c/ul\u003e\u003cblockquote\u003e\u003cp id=\"24a2\"\u003e\u003cem\u003e“Why did the developer bring a ladder to the code review? To handle high-level exceptions!”\u003c/em\u003e\u003c/p\u003e\u003c/blockquote\u003e\u003ch2 id=\"4b9c\"\u003e2. Checked vs. Unchecked Exceptions\u003c/h2\u003e\u003cp id=\"34ac\"\u003eUnlike Java, Kotlin doesn’t differentiate between checked and unchecked exceptions. All exceptions are unchecked, meaning that the compiler doesn’t force you to handle them. This design simplifies code and avoids boilerplate.\u003c/p\u003e\u003cfigure\u003e\u003c/figure\u003e\u003cp id=\"6861\"\u003e\u003cstrong\u003eExplanation:\u003c/strong\u003e\u003c/p\u003e\u003cul\u003e\u003cli id=\"0582\"\u003eChecked exceptions require explicit handling, often leading to verbose code.\u003c/li\u003e\u003cli id=\"755a\"\u003eKotlin’s approach aligns with modern development practices, emphasizing developer responsibility over compiler enforcement.\u003c/li\u003e\u003c/ul\u003e\u003ch2 id=\"c20c\"\u003e3. Custom Exceptions\u003c/h2\u003e\u003cp id=\"92a7\"\u003eKotlin allows developers to define custom exceptions for more granular error handling.\u003c/p\u003e\u003cpre\u003e\u003cspan id=\"1769\"\u003eclass InvalidInputException(message: String) : Exception(message)\u003cp\u003efun validateInput(input: Int) {\u003cbr/\u003e    if (input \u0026lt; 0) {\u003cbr/\u003e        throw InvalidInputException(\u0026#34;Input must be non-negative\u0026#34;)\u003cbr/\u003e    }\u003cbr/\u003e}\u003cbr/\u003efun main() {\u003cbr/\u003e    try {\u003cbr/\u003e        validateInput(-5)\u003cbr/\u003e    } catch (e: InvalidInputException) {\u003cbr/\u003e        println(\u0026#34;Caught Exception: ${e.message}\u0026#34;)\u003cbr/\u003e    }\u003cbr/\u003e}\u003c/p\u003e\u003c/span\u003e\u003c/pre\u003e\u003cp id=\"9d92\"\u003e\u003cstrong\u003eExplanation:\u003c/strong\u003e\u003c/p\u003e\u003cul\u003e\u003cli id=\"a1b5\"\u003eCustom exceptions provide clarity by allowing you to communicate domain-specific issues.\u003c/li\u003e\u003cli id=\"d1df\"\u003eThis makes debugging easier as the exception conveys exactly what went wrong.\u003c/li\u003e\u003c/ul\u003e\u003cblockquote\u003e\u003cp id=\"10af\"\u003eThrowing custom exceptions is like saying, \u003cem\u003e“This is my circus, and these are my monkeys.”\u003c/em\u003e\u003c/p\u003e\u003c/blockquote\u003e\u003cp id=\"0310\"\u003eCustom exceptions help in creating domain-specific error-handling mechanisms.\u003c/p\u003e\u003ch2 id=\"7130\"\u003e4. Null Safety and the Elvis Operator\u003c/h2\u003e\u003cp id=\"459f\"\u003eKotlin’s null safety features significantly reduce the chances of \u003ccode\u003eNullPointerException\u003c/code\u003e. The Elvis operator (\u003ccode\u003e?:\u003c/code\u003e) provides a concise way to handle nullable types.\u003c/p\u003e\u003cpre\u003e\u003cspan id=\"9a41\"\u003efun getLength(str: String?): Int {\u003cbr/\u003e    return str?.length ?: 0\u003cbr/\u003e}\u003cp\u003efun main() {\u003cbr/\u003e    println(getLength(null)) // Outputs: 0\u003cbr/\u003e}\u003c/p\u003e\u003c/span\u003e\u003c/pre\u003e\u003cp id=\"8638\"\u003e\u003cstrong\u003eExplanation:\u003c/strong\u003e\u003c/p\u003e\u003cul\u003e\u003cli id=\"ce92\"\u003eThe \u003ccode\u003e?.\u003c/code\u003e operator safely accesses properties of nullable types.\u003c/li\u003e\u003cli id=\"c4c6\"\u003eThe Elvis operator (\u003ccode\u003e?:\u003c/code\u003e) provides a default value if the expression to its left evaluates to \u003ccode\u003enull\u003c/code\u003e.\u003c/li\u003e\u003c/ul\u003e\u003cblockquote\u003e\u003cp id=\"ce5d\"\u003eNull safety: Because Kotlin knows that “To null is human, but to not null is divine.”\u003c/p\u003e\u003c/blockquote\u003e\u003cp id=\"7705\"\u003eHere, the Elvis operator ensures that a default value is returned if \u003ccode\u003estr\u003c/code\u003e is null.\u003c/p\u003e\u003ch2 id=\"3f9f\"\u003e5. Double Bang Operator\u003c/h2\u003e\u003cp id=\"67e5\"\u003eThe \u003cstrong\u003edouble bang operator (\u003c/strong\u003e\u003ccode\u003e\u003cstrong\u003e!!\u003c/strong\u003e\u003c/code\u003e\u003cstrong\u003e)\u003c/strong\u003e is used to explicitly assert that an expression is \u003cstrong\u003enon-null\u003c/strong\u003e. When you use \u003ccode\u003e!!\u003c/code\u003e, you tell the compiler: \u0026#34;I know this value is not null, so proceed as if it\u0026#39;s non-null.\u0026#34;\u003c/p\u003e\u003cp id=\"ca9b\"\u003eIf the value \u003cstrong\u003eis null\u003c/strong\u003e, it throws a \u003ccode\u003eNullPointerException\u003c/code\u003e (NPE) at runtime. This operator is risky and should be used sparingly because it bypasses Kotlin\u0026#39;s built-in null safety.\u003c/p\u003e\u003cp id=\"76bf\"\u003e\u003cstrong\u003eSyntax of the Double Bang Operator\u003c/strong\u003e\u003c/p\u003e\u003cpre\u003e\u003cspan id=\"e30f\"\u003eval nonNullableValue = nullableValue!!\u003c/span\u003e\u003c/pre\u003e\u003cul\u003e\u003cli id=\"caa2\"\u003eIf \u003ccode\u003enullableValue\u003c/code\u003e is non-null, the program continues normally.\u003c/li\u003e\u003cli id=\"ad25\"\u003eIf \u003ccode\u003enullableValue\u003c/code\u003e is null, the program crashes with a \u003ccode\u003eNullPointerException\u003c/code\u003e.\u003c/li\u003e\u003c/ul\u003e\u003cp id=\"d796\"\u003e\u003cstrong\u003eExample 1 : Basic Exception Handling with \u003c/strong\u003e\u003ccode\u003e\u003cstrong\u003e!!\u003cbr/\u003e\u003c/strong\u003e\u003c/code\u003eTo handle exceptions caused by the double bang operator, you can wrap it in a \u003ccode\u003etry-catch\u003c/code\u003e block.\u003c/p\u003e\u003cpre\u003e\u003cspan id=\"5f6b\"\u003efun main() {\u003cbr/\u003e    val name: String? = null\u003cbr/\u003e    try {\u003cbr/\u003e            val length = name!!.length // Forces an exception if `name` is null\u003cbr/\u003e            println(\u0026#34;Length of the name: $length\u0026#34;)\u003cbr/\u003e        } catch (e: NullPointerException) {\u003cbr/\u003e            println(\u0026#34;Caught a NullPointerException: ${e.message}\u0026#34;)\u003cbr/\u003e        }\u003cbr/\u003e}\u003c/span\u003e\u003c/pre\u003e\u003cp id=\"ff8a\"\u003e\u003cstrong\u003eOutput:\u003c/strong\u003e\u003c/p\u003e\u003cpre\u003e\u003cspan id=\"019c\"\u003eCaught a NullPointerException: null\u003c/span\u003e\u003c/pre\u003e\u003cp id=\"d260\"\u003eHere, the \u003ccode\u003eNullPointerException\u003c/code\u003e is caught, and the program doesn\u0026#39;t crash.\u003c/p\u003e\u003cp id=\"48a1\"\u003e\u003cstrong\u003eWhen to Use \u003c/strong\u003e\u003ccode\u003e\u003cstrong\u003e!!\u003cbr/\u003e\u003c/strong\u003e\u003c/code\u003eYou should avoid \u003ccode\u003e!!\u003c/code\u003e whenever possible. Use it \u003cstrong\u003eonly\u003c/strong\u003e when:\u003c/p\u003e\u003col\u003e\u003cli id=\"e8b0\"\u003eYou are 100% certain that a value is non-null at runtime.\u003c/li\u003e\u003cli id=\"a73e\"\u003eYou want the program to explicitly throw an exception when a null value is unexpected.\u003c/li\u003e\u003c/ol\u003e\u003cp id=\"8843\"\u003e\u003cstrong\u003eExample 2: Legitimate Use Case for \u003c/strong\u003e\u003ccode\u003e\u003cstrong\u003e!!\u003c/strong\u003e\u003c/code\u003e\u003c/p\u003e\u003cpre\u003e\u003cspan id=\"5499\"\u003efun getNameLength(name: String?): Int {\u003cbr/\u003e    return name!!.length // You are certain `name` is not null here\u003cbr/\u003e}\u003cbr/\u003efun main() {\u003cbr/\u003e    val name: String? = \u0026#34;Kotlin\u0026#34;\u003cbr/\u003e    println(\u0026#34;Length of the name: ${getNameLength(name)}\u0026#34;) // Works as expected\u003cbr/\u003e}\u003c/span\u003e\u003c/pre\u003e\u003cp id=\"4d6f\"\u003eHere, \u003ccode\u003e!!\u003c/code\u003e is used when you are certain that \u003ccode\u003ename\u003c/code\u003e will not be null.\u003c/p\u003e\u003cp id=\"594d\"\u003eThe double bang operator is a powerful but dangerous tool. \u003cstrong\u003e\u003cem\u003eIt’s better to rely on Kotlin’s null safety features (\u003c/em\u003e\u003c/strong\u003e\u003ccode\u003e\u003cstrong\u003e\u003cem\u003e?.\u003c/em\u003e\u003c/strong\u003e\u003c/code\u003e\u003cstrong\u003e\u003cem\u003e, \u003c/em\u003e\u003c/strong\u003e\u003ccode\u003e\u003cstrong\u003e\u003cem\u003e?:\u003c/em\u003e\u003c/strong\u003e\u003c/code\u003e\u003cstrong\u003e\u003cem\u003e, \u003c/em\u003e\u003c/strong\u003e\u003ccode\u003e\u003cstrong\u003e\u003cem\u003elet\u003c/em\u003e\u003c/strong\u003e\u003c/code\u003e\u003cstrong\u003e\u003cem\u003e, \u003c/em\u003e\u003c/strong\u003e\u003ccode\u003e\u003cstrong\u003e\u003cem\u003eif\u003c/em\u003e\u003c/strong\u003e\u003c/code\u003e\u003cstrong\u003e\u003cem\u003e, etc.) \u003c/em\u003e\u003c/strong\u003eto handle nulls gracefully. Reserve \u003ccode\u003e!!\u003c/code\u003e for situations where you need strict null-safety enforcement and are willing to risk throwing an exception.\u003c/p\u003e\u003ch2 id=\"aa06\"\u003e6. Result Type\u003c/h2\u003e\u003cp id=\"e069\"\u003eKotlin’s \u003ccode\u003eResult\u003c/code\u003e type is a functional approach to handle success and failure cases without exceptions.\u003c/p\u003e\u003cpre\u003e\u003cspan id=\"65ec\"\u003efun safeDivide(a: Int, b: Int): Result\u0026lt;Int\u0026gt; {\u003cbr/\u003e    return if (b != 0) {\u003cbr/\u003e        Result.success(a / b)\u003cbr/\u003e    } else {\u003cbr/\u003e        Result.failure(ArithmeticException(\u0026#34;Division by zero\u0026#34;))\u003cbr/\u003e    }\u003cbr/\u003e}\u003c/span\u003e\u003c/pre\u003e\u003cpre\u003e\u003cspan id=\"061e\"\u003efun main() {\u003cbr/\u003e    val result = safeDivide(10, 0)\u003cbr/\u003e    result.onSuccess {\u003cbr/\u003e        println(\u0026#34;Result: $it\u0026#34;)\u003cbr/\u003e    }.onFailure {\u003cbr/\u003e        println(\u0026#34;Error: ${it.message}\u0026#34;)\u003cbr/\u003e    }\u003cbr/\u003e}\u003c/span\u003e\u003c/pre\u003e\u003cp id=\"bf5c\"\u003e\u003cstrong\u003eExplanation:\u003c/strong\u003e\u003c/p\u003e\u003cul\u003e\u003cli id=\"1bc4\"\u003e\u003ccode\u003eResult\u003c/code\u003e encapsulates success or failure, avoiding the need for explicit exception handling.\u003c/li\u003e\u003cli id=\"da58\"\u003eThe \u003ccode\u003eonSuccess\u003c/code\u003e and \u003ccode\u003eonFailure\u003c/code\u003e methods allow you to handle both outcomes succinctly.\u003c/li\u003e\u003c/ul\u003e\u003cblockquote\u003e\u003cp id=\"57af\"\u003eIt’s like playing a game of chance: \u003cem\u003e“Heads, you succeed. Tails, you divide by zero.”\u003c/em\u003e\u003c/p\u003e\u003c/blockquote\u003e\u003ch2 id=\"4254\"\u003e\u003ccode\u003e7. \u0026#34;runCatching\u0026#34;\u003c/code\u003e for Exception Handling\u003c/h2\u003e\u003cp id=\"48d3\"\u003eUsing \u003ccode\u003eResult\u003c/code\u003e provides a clear separation of successful and error outcomes, promoting functional programming practices.\u003c/p\u003e\u003cp id=\"7fc2\"\u003eIn Kotlin, the \u003ccode\u003erunCatching\u003c/code\u003e function is a handy utility for encapsulating the result of a block of code execution. It simplifies exception handling by wrapping the result of a code block in a \u003ccode\u003eResult\u003c/code\u003e object. If the code executes successfully, it encapsulates the result as a \u003ccode\u003eSuccess\u003c/code\u003e. If an exception occurs, it catches it and encapsulates it as a \u003ccode\u003eFailure\u003c/code\u003e.\u003c/p\u003e\u003cp id=\"5051\"\u003eHere’s a breakdown of how \u003ccode\u003erunCatching\u003c/code\u003e works:\u003c/p\u003e\u003cul\u003e\u003cli id=\"86be\"\u003e\u003cstrong\u003eInput:\u003c/strong\u003e A lambda block of code to execute.\u003c/li\u003e\u003cli id=\"c89a\"\u003e\u003cstrong\u003eOutput:\u003c/strong\u003e A \u003ccode\u003eResult\u003c/code\u003e object that can represent either:\u003cbr/\u003e\u003ccode\u003eSuccess\u003c/code\u003e if the block executes without exceptions.\u003cbr/\u003e\u003ccode\u003eFailure\u003c/code\u003e if any exception (of type \u003ccode\u003eThrowable\u003c/code\u003e) occurs during execution.\u003c/li\u003e\u003c/ul\u003e\u003cp id=\"76e8\"\u003eThis allows you to handle errors and process results more functionally.\u003c/p\u003e\u003cpre\u003e\u003cspan id=\"908a\"\u003efun main() {\u003cbr/\u003e    val result = runCatching {\u003cbr/\u003e        // Block of code that might throw an exception\u003cbr/\u003e        val number = \u0026#34;123\u0026#34;.toInt() // This will succeed\u003cbr/\u003e        number / 0                // This will throw an ArithmeticException\u003cbr/\u003e    }\u003cp\u003e    // Handling the result\u003cbr/\u003e    result.onSuccess { value -\u0026gt;\u003cbr/\u003e        println(\u0026#34;Success! The result is $value\u0026#34;)\u003cbr/\u003e    }.onFailure { exception -\u0026gt;\u003cbr/\u003e        println(\u0026#34;Failure! Caught exception: ${exception.message}\u0026#34;)\u003cbr/\u003e    }\u003cbr/\u003e}\u003c/p\u003e\u003c/span\u003e\u003c/pre\u003e\u003cp id=\"ee0d\"\u003e\u003cstrong\u003eExplanation:\u003c/strong\u003e\u003c/p\u003e\u003col\u003e\u003cli id=\"6d70\"\u003eThe block in \u003ccode\u003erunCatching\u003c/code\u003e contains code that attempts to:\u003c/li\u003e\u003c/ol\u003e\u003cul\u003e\u003cli id=\"5839\"\u003eParse a string to an integer (\u003ccode\u003e\u0026#34;123\u0026#34;.toInt()\u003c/code\u003e) – successful.\u003c/li\u003e\u003cli id=\"98d9\"\u003eDivide the number by zero — throws an \u003ccode\u003eArithmeticException\u003c/code\u003e.\u003c/li\u003e\u003c/ul\u003e\u003cp id=\"9860\"\u003e2. Since the second operation fails, the exception is caught, and the result is encapsulated as \u003ccode\u003eFailure\u003c/code\u003e.\u003c/p\u003e\u003cp id=\"abba\"\u003e3. The result is then handled:\u003c/p\u003e\u003cul\u003e\u003cli id=\"f53e\"\u003e\u003ccode\u003e\u003cstrong\u003eonSuccess\u003c/strong\u003e\u003c/code\u003e\u003cstrong\u003e block:\u003c/strong\u003e Will execute if the operation succeeds.\u003c/li\u003e\u003cli id=\"64ba\"\u003e\u003ccode\u003e\u003cstrong\u003eonFailure\u003c/strong\u003e\u003c/code\u003e\u003cstrong\u003e block:\u003c/strong\u003e Will execute if an exception is caught, and it provides the exception details.\u003c/li\u003e\u003c/ul\u003e\u003cp id=\"e789\"\u003e\u003cstrong\u003ePractical Use Case: Reading a File\u003c/strong\u003e\u003c/p\u003e\u003cpre\u003e\u003cspan id=\"1e64\"\u003efun readFileContent(fileName: String): String {\u003cbr/\u003e    return runCatching {\u003cbr/\u003e        // Simulating reading a file\u003cbr/\u003e        if (fileName.isBlank()) throw IllegalArgumentException(\u0026#34;File name cannot be blank\u0026#34;)\u003cbr/\u003e        \u0026#34;File content of $fileName\u0026#34;\u003cbr/\u003e    }.getOrElse { exception -\u0026gt;\u003cbr/\u003e        \u0026#34;Error occurred: ${exception.message}\u0026#34;\u003cbr/\u003e    }\u003cbr/\u003e}\u003cp\u003efun main() {\u003cbr/\u003e    println(readFileContent(\u0026#34;document.txt\u0026#34;))  // Successful case\u003cbr/\u003e    println(readFileContent(\u0026#34;\u0026#34;))              // Failure case\u003cbr/\u003e}\u003c/p\u003e\u003c/span\u003e\u003c/pre\u003e\u003cp id=\"2336\"\u003e\u003cstrong\u003eOutput:\u003c/strong\u003e\u003c/p\u003e\u003cpre\u003e\u003cspan id=\"c150\"\u003eFile content of document.txt\u003cbr/\u003eError occurred: File name cannot be blank\u003c/span\u003e\u003c/pre\u003e\u003cp id=\"6b85\"\u003e\u003cstrong\u003eKey Benefits of \u003c/strong\u003e\u003ccode\u003e\u003cstrong\u003erunCatching\u003c/strong\u003e\u003c/code\u003e\u003cstrong\u003e:\u003c/strong\u003e\u003c/p\u003e\u003cul\u003e\u003cli id=\"032a\"\u003eConcise exception handling.\u003c/li\u003e\u003cli id=\"789f\"\u003eAvoids boilerplate \u003ccode\u003etry-catch\u003c/code\u003e blocks.\u003c/li\u003e\u003cli id=\"b2e5\"\u003eFunctional programming style: chaining methods like \u003ccode\u003eonSuccess\u003c/code\u003e, \u003ccode\u003eonFailure\u003c/code\u003e, \u003ccode\u003emap\u003c/code\u003e, and \u003ccode\u003egetOrElse\u003c/code\u003e for clean handling of both success and failure scenarios.\u003c/li\u003e\u003c/ul\u003e\u003c/div\u003e\u003cdiv\u003e\u003ch2 id=\"418a\"\u003eError Handling in Coroutines in Kotlin: A Deep Dive\u003c/h2\u003e\u003cp id=\"9870\"\u003eKotlin coroutines provide a powerful way to write asynchronous and non-blocking code. However, handling errors effectively in coroutines requires a good understanding of coroutine-specific mechanisms and best practices. Below are key strategies for error handling in coroutines.\u003c/p\u003e\u003ch2 id=\"84ae\"\u003e8. Exception Handling in Coroutines\u003c/h2\u003e\u003cp id=\"08dd\"\u003eIn Kotlin, exceptions in coroutines are propagated differently based on the coroutine builder used. The most commonly used builders are \u003ccode\u003elaunch\u003c/code\u003e and \u003ccode\u003easync\u003c/code\u003e.\u003c/p\u003e\u003cul\u003e\u003cli id=\"703e\"\u003e\u003ccode\u003e\u003cstrong\u003elaunch\u003c/strong\u003e\u003c/code\u003e: Exceptions are propagated to the \u003ccode\u003eCoroutineExceptionHandler\u003c/code\u003e.\u003c/li\u003e\u003cli id=\"879c\"\u003e\u003ccode\u003e\u003cstrong\u003easync\u003c/strong\u003e\u003c/code\u003e: Exceptions are deferred and must be caught when accessing the result.\u003c/li\u003e\u003c/ul\u003e\u003cpre\u003e\u003cspan id=\"2a83\"\u003eimport kotlinx.coroutines.*\u003cp\u003efun main() = runBlocking {\u003cbr/\u003e    val job = launch {\u003cbr/\u003e        try {\u003cbr/\u003e            println(\u0026#34;Throwing exception in launch\u0026#34;)\u003cbr/\u003e            throw IllegalArgumentException(\u0026#34;Exception in launch\u0026#34;)\u003cbr/\u003e        } catch (e: Exception) {\u003cbr/\u003e            println(\u0026#34;Caught ${e.message}\u0026#34;)\u003cbr/\u003e        }\u003cbr/\u003e    }\u003cbr/\u003e    job.join()\u003cbr/\u003e    val deferred = async {\u003cbr/\u003e        println(\u0026#34;Throwing exception in async\u0026#34;)\u003cbr/\u003e        throw IllegalArgumentException(\u0026#34;Exception in async\u0026#34;)\u003cbr/\u003e    }\u003cbr/\u003e    try {\u003cbr/\u003e        deferred.await()\u003cbr/\u003e    } catch (e: Exception) {\u003cbr/\u003e        println(\u0026#34;Caught ${e.message}\u0026#34;)\u003cbr/\u003e    }\u003cbr/\u003e}\u003c/p\u003e\u003c/span\u003e\u003c/pre\u003e\u003cp id=\"1fe8\"\u003e\u003cstrong\u003eExplanation:\u003c/strong\u003e\u003c/p\u003e\u003cul\u003e\u003cli id=\"d807\"\u003e\u003ccode\u003elaunch\u003c/code\u003e: Automatically propagates uncaught exceptions to its parent or a \u003ccode\u003eCoroutineExceptionHandler\u003c/code\u003e.\u003c/li\u003e\u003cli id=\"3575\"\u003e\u003ccode\u003easync\u003c/code\u003e: Requires explicit handling when the result is awaited.\u003c/li\u003e\u003c/ul\u003e\u003cblockquote\u003e\u003cp id=\"fcc1\"\u003e\u003cem\u003e“Async errors: Because sometimes you just need a little delay to let the chaos unfold.”\u003c/em\u003e\u003c/p\u003e\u003c/blockquote\u003e\u003ch2 id=\"e3f4\"\u003e9. CoroutineExceptionHandler\u003c/h2\u003e\u003cp id=\"aea8\"\u003eThe \u003ccode\u003eCoroutineExceptionHandler\u003c/code\u003e is a dedicated mechanism for handling uncaught exceptions in coroutines launched via \u003ccode\u003elaunch\u003c/code\u003e.\u003c/p\u003e\u003cpre\u003e\u003cspan id=\"6197\"\u003eimport kotlinx.coroutines.*\u003cp\u003efun main() = runBlocking {\u003cbr/\u003e    val handler = CoroutineExceptionHandler { _, exception -\u0026gt;\u003cbr/\u003e        println(\u0026#34;Caught ${exception.message} in CoroutineExceptionHandler\u0026#34;)\u003cbr/\u003e    }\u003cbr/\u003e    val job = launch(handler) {\u003cbr/\u003e        throw IllegalStateException(\u0026#34;Unhandled exception\u0026#34;)\u003cbr/\u003e    }\u003cbr/\u003e    job.join()\u003cbr/\u003e}\u003c/p\u003e\u003c/span\u003e\u003c/pre\u003e\u003cp id=\"c6ab\"\u003e\u003cstrong\u003eExplanation:\u003c/strong\u003e\u003c/p\u003e\u003cul\u003e\u003cli id=\"c2ff\"\u003eActs as a global handler for uncaught exceptions in coroutines.\u003c/li\u003e\u003cli id=\"87ff\"\u003eCan be attached to a \u003ccode\u003eCoroutineScope\u003c/code\u003e or individual coroutines.\u003c/li\u003e\u003c/ul\u003e\u003cblockquote\u003e\u003cp id=\"b44e\"\u003e\u003cem\u003e“CoroutineExceptionHandler: The guardian angel your coroutines never knew they needed.”\u003c/em\u003e\u003c/p\u003e\u003c/blockquote\u003e\u003ch2 id=\"8786\"\u003e10. SupervisionJob and SupervisorScope\u003c/h2\u003e\u003cp id=\"918b\"\u003eWhen working with structured concurrency, \u003ccode\u003eSupervisorJob\u003c/code\u003e and \u003ccode\u003esupervisorScope\u003c/code\u003e allow child coroutines to fail independently without affecting others.\u003c/p\u003e\u003cpre\u003e\u003cspan id=\"c089\"\u003eimport kotlinx.coroutines.*\u003cp\u003efun main() = runBlocking {\u003cbr/\u003e    supervisorScope {\u003cbr/\u003e        val child1 = launch {\u003cbr/\u003e            println(\u0026#34;Child 1 is running\u0026#34;)\u003cbr/\u003e            throw RuntimeException(\u0026#34;Child 1 failed\u0026#34;)\u003cbr/\u003e        }\u003cbr/\u003e        val child2 = launch {\u003cbr/\u003e            println(\u0026#34;Child 2 is running\u0026#34;)\u003cbr/\u003e            delay(1000)\u003cbr/\u003e            println(\u0026#34;Child 2 completed\u0026#34;)\u003cbr/\u003e        }\u003cbr/\u003e        try {\u003cbr/\u003e            child1.join()\u003cbr/\u003e        } catch (e: Exception) {\u003cbr/\u003e            println(\u0026#34;Caught exception from child 1: ${e.message}\u0026#34;)\u003cbr/\u003e        }\u003cbr/\u003e        child2.join()\u003cbr/\u003e    }\u003cbr/\u003e}\u003c/p\u003e\u003c/span\u003e\u003c/pre\u003e\u003cp id=\"7eb8\"\u003e\u003cstrong\u003eExplanation:\u003c/strong\u003e\u003c/p\u003e\u003cul\u003e\u003cli id=\"b68a\"\u003e\u003ccode\u003eSupervisorJob\u003c/code\u003e ensures that failure in one child coroutine doesn’t cancel others.\u003c/li\u003e\u003cli id=\"ae03\"\u003e\u003ccode\u003esupervisorScope\u003c/code\u003e works similarly, providing isolation for child coroutine errors.\u003c/li\u003e\u003c/ul\u003e\u003cblockquote\u003e\u003cp id=\"6645\"\u003e\u003cem\u003e“Supervision: Because even coroutines need a responsible adult in the room.”\u003c/em\u003e\u003c/p\u003e\u003c/blockquote\u003e\u003ch2 id=\"8f2f\"\u003eWhy Exception Handling is Important in Coroutines\u003c/h2\u003e\u003cp id=\"f76a\"\u003eException handling in coroutines is critical due to their asynchronous and concurrent nature. Here’s why:\u003c/p\u003e\u003col\u003e\u003cli id=\"9245\"\u003e\u003cstrong\u003eUncaught Exceptions Can Crash Your Application:\u003c/strong\u003e Unhandled exceptions in coroutines launched in the \u003ccode\u003eGlobalScope\u003c/code\u003e or at the top level may lead to application crashes. This is especially risky in production environments.\u003c/li\u003e\u003cli id=\"a518\"\u003e\u003cstrong\u003eComplex Error Propagation:\u003c/strong\u003e Coroutines are designed to handle concurrency. Without proper error handling, debugging and tracing the source of exceptions can become a nightmare.\u003c/li\u003e\u003cli id=\"7388\"\u003e\u003cstrong\u003eStructured Concurrency Needs Predictability:\u003c/strong\u003e In structured concurrency, the parent coroutine supervises its children. Unhandled exceptions in child coroutines can affect parent coroutines, causing unintended cancellations.\u003c/li\u003e\u003cli id=\"65ff\"\u003e\u003cstrong\u003eGraceful Recovery:\u003c/strong\u003e Applications often need to continue functioning even after encountering an error. Handling exceptions enables recovery mechanisms, such as retries or fallback logic.\u003c/li\u003e\u003c/ol\u003e\u003ch2 id=\"89ee\"\u003eConclusion\u003c/h2\u003e\u003cp id=\"d0c7\"\u003eKotlin provides powerful error-handling tools, from traditional \u003ccode\u003etry-catch\u003c/code\u003e blocks to coroutine-specific mechanisms like \u003ccode\u003eCoroutineExceptionHandler\u003c/code\u003e and \u003ccode\u003esupervisorScope\u003c/code\u003e. Mastering these techniques ensures your applications are robust, maintainable, and resilient to errors.\u003c/p\u003e\u003cp id=\"7b29\"\u003eRemember, good error handling isn’t just about preventing crashes — it’s about ensuring that your application can recover gracefully and continue to provide a great user experience. And if all else fails, at least you’ll have some funny error messages to entertain your users!\u003c/p\u003e\u003c/div\u003e\u003c/div\u003e",
  "readingTime": "14 min read",
  "publishedTime": "2024-12-23T14:36:21.557Z",
  "modifiedTime": null
}
